<?xml version="1.0" encoding="utf-8"?>
<!-- This URDF was automatically created by SolidWorks to URDF Exporter! Originally created by Stephen Brawner (brawner@gmail.com) 
     Commit Version: 1.6.0-4-g7f85cfe  Build Version: 1.6.7995.38578
     For more information, please see http://wiki.ros.org/sw_urdf_exporter -->
<robot
  name="cal_rtheta">
  <link
    name="base_link">
    <inertial>
      <origin
        xyz="0.00160370698815008 0.0107956954478326 -0.149734037395244"
        rpy="0 0 0" />
      <mass
        value="1.76467094746733" />
      <inertia
        ixx="0.0130581328928144"
        ixy="-4.54713146541741E-11"
        ixz="-1.50763492548379E-11"
        iyy="0.012826657586942"
        iyz="1.82018199533536E-08"
        izz="0.0107367180747605" />
    </inertial>
    <visual>
      <origin
        xyz="0 0 0"
        rpy="0 0 0" />
      <geometry>
        <mesh
          filename="package://cal_rtheta/meshes/base_link.STL" />
      </geometry>
      <material
        name="">
        <color
          rgba="0.792156862745098 0.819607843137255 0.933333333333333 1" />
      </material>
    </visual>
    <collision>
      <origin
        xyz="0 0 0"
        rpy="0 0 0" />
      <geometry>
        <mesh
          filename="package://cal_rtheta/meshes/base_link.STL" />
      </geometry>
    </collision>
  </link>
  <link
    name="arm1">
    <inertial>
      <origin
        xyz="0.0321312312401677 0.00767337913274497 0.0561714750171738"
        rpy="0 0 0" />
      <mass
        value="0.520980619278063" />
      <inertia
        ixx="5.32801426885152E-05"
        ixy="-1.54634068031781E-07"
        ixz="3.60329649668308E-07"
        iyy="0.0177374579527826"
        iyz="-3.00575800425227E-07"
        izz="0.0177519568501521" />
    </inertial>
    <visual>
      <origin
        xyz="0 0 0"
        rpy="0 0 0" />
      <geometry>
        <mesh
          filename="package://cal_rtheta/meshes/arm1.STL" />
      </geometry>
      <material
        name="">
        <color
          rgba="0.898039215686275 0.917647058823529 0.929411764705882 1" />
      </material>
    </visual>
    <collision>
      <origin
        xyz="0 0 0"
        rpy="0 0 0" />
      <geometry>
        <mesh
          filename="package://cal_rtheta/meshes/arm1.STL" />
      </geometry>
    </collision>
  </link>
  <joint
    name="arm1"
    type="revolute">
    <origin
      xyz="0 0 0"
      rpy="0 0 0" />
    <parent
      link="base_link" />
    <child
      link="arm1" />
    <axis
      xyz="0 0 1" />
    <limit
      lower="-1.57"
      upper="1.57"
      effort="0"
      velocity="0" />
  </joint>
  <link
    name="arm2">
    <inertial>
      <origin
        xyz="-0.112046931785968 0.00807132056444097 0.0798883371270733"
        rpy="0 0 0" />
      <mass
        value="0.23038173051872" />
      <inertia
        ixx="2.25590856139683E-05"
        ixy="-4.01371823348448E-08"
        ixz="-2.39672498571332E-06"
        iyy="0.00774508128437316"
        iyz="-4.62819160081638E-08"
        izz="0.00775520436890299" />
    </inertial>
    <visual>
      <origin
        xyz="0 0 0"
        rpy="0 0 0" />
      <geometry>
        <mesh
          filename="package://cal_rtheta/meshes/arm2.STL" />
      </geometry>
      <material
        name="">
        <color
          rgba="0.792156862745098 0.819607843137255 0.933333333333333 1" />
      </material>
    </visual>
    <collision>
      <origin
        xyz="0 0 0"
        rpy="0 0 0" />
      <geometry>
        <mesh
          filename="package://cal_rtheta/meshes/arm2.STL" />
      </geometry>
    </collision>
  </link>
  <joint
    name="arm2"
    type="prismatic">
    <origin
      xyz="0 0 0"
      rpy="0 0 0" />
    <parent
      link="arm1" />
    <child
      link="arm2" />
    <axis
      xyz="-1 0 0" />
    <limit
      lower="0"
      upper="0.56"
      effort="0"
      velocity="0" />
  </joint>
  <link
    name="hand">
    <inertial>
      <origin
        xyz="-0.00164999996620452 -0.291950472017807 2.95354192492159E-12"
        rpy="0 0 0" />
      <mass
        value="0.0507440794437005" />
      <inertia
        ixx="0.000887163780501905"
        ixy="1.66683716552311E-18"
        ixz="-4.13928578344086E-23"
        iyy="1.53912665246415E-06"
        iyz="1.20002928510094E-18"
        izz="0.000887170174433718" />
    </inertial>
    <visual>
      <origin
        xyz="0 0 0"
        rpy="0 0 0" />
      <geometry>
        <mesh
          filename="package://cal_rtheta/meshes/hand.STL" />
      </geometry>
      <material
        name="">
        <color
          rgba="0.898039215686275 0.917647058823529 0.929411764705882 1" />
      </material>
    </visual>
    <collision>
      <origin
        xyz="0 0 0"
        rpy="0 0 0" />
      <geometry>
        <mesh
          filename="package://cal_rtheta/meshes/hand.STL" />
      </geometry>
    </collision>
  </link>
  <joint
    name="hand"
    type="prismatic">
    <origin
      xyz="-0.510196777139376 0.00800000000294753 0.0905000000000032"
      rpy="1.5707963267949 0 0" />
    <parent
      link="arm2" />
    <child
      link="hand" />
    <axis
      xyz="0 1 0" />
    <limit
      lower="0"
      upper="0.3"
      effort="0"
      velocity="0" />
  </joint>
  <link
    name="end_ef">
    <inertial>
      <origin
        xyz="-0.0013899041319213 -0.504768064263372 -0.000162849640309571"
        rpy="0 0 0" />
      <mass
        value="0.04000259246509" />
      <inertia
        ixx="0.00011955615933602"
        ixy="9.12217224199443E-09"
        ixz="-1.12000746263978E-14"
        iyy="0.000120606727718704"
        iyz="6.97884337766864E-15"
        izz="2.39738428964408E-06" />
    </inertial>
    <visual>
      <origin
        xyz="0 0 0"
        rpy="0 0 0" />
      <geometry>
        <mesh
          filename="package://cal_rtheta/meshes/end_ef.STL" />
      </geometry>
      <material
        name="">
        <color
          rgba="0.792156862745098 0.819607843137255 0.933333333333333 1" />
      </material>
    </visual>
    <collision>
      <origin
        xyz="0 0 0"
        rpy="0 0 0" />
      <geometry>
        <mesh
          filename="package://cal_rtheta/meshes/end_ef.STL" />
      </geometry>
    </collision>
  </link>
  <joint
    name="end_ef"
    type="revolute">
    <origin
      xyz="0 0 0"
      rpy="0 0 0" />
    <parent
      link="hand" />
    <child
      link="end_ef" />
    <axis
      xyz="0 1 0" />
    <limit
      lower="0"
      upper="3.14"
      effort="0"
      velocity="0" />
  </joint>
  <link
    name="end_ef_45">
    <inertial>
      <origin
        xyz="0.00144067958468752 -0.549677963475141 0.000751786061722646"
        rpy="0 0 0" />
      <mass
        value="0.106532639841428" />
      <inertia
        ixx="3.7155746212921E-05"
        ixy="-5.81396477076448E-06"
        ixz="-1.46333627560176E-07"
        iyy="2.85728922535102E-05"
        iyz="-5.12534505722177E-07"
        izz="2.92404250341568E-05" />
    </inertial>
    <visual>
      <origin
        xyz="0 0 0"
        rpy="0 0 0" />
      <geometry>
        <mesh
          filename="package://cal_rtheta/meshes/end_ef_45.STL" />
      </geometry>
      <material
        name="">
        <color
          rgba="0.792156862745098 0.819607843137255 0.933333333333333 1" />
      </material>
    </visual>
    <collision>
      <origin
        xyz="0 0 0"
        rpy="0 0 0" />
      <geometry>
        <mesh
          filename="package://cal_rtheta/meshes/end_ef_45.STL" />
      </geometry>
    </collision>
  </link>
  <joint
    name="end_ef_45"
    type="revolute">
    <origin
      xyz="0 0 0"
      rpy="0 0 0" />
    <parent
      link="end_ef" />
    <child
      link="end_ef_45" />
    <axis
      xyz="0 1 0" />
    <limit
      lower="0"
      upper="0.78"
      effort="0"
      velocity="0" />
  </joint>
</robot>